2022-05-05 13:55:04,779 INFO    MainThread:190045 [internal.py:wandb_internal():90] W&B internal server running at pid: 190045, started at: 2022-05-05 13:55:04.779002
2022-05-05 13:55:04,780 INFO    WriterThread:190045 [datastore.py:open_for_write():75] open: /home/river/interbotix_ws/src/chessbot/src/wandb/run-20220505_135504-301jv4u6/run-301jv4u6.wandb
2022-05-05 13:55:04,782 DEBUG   SenderThread:190045 [sender.py:send():232] send: header
2022-05-05 13:55:04,782 DEBUG   SenderThread:190045 [sender.py:send():232] send: run
2022-05-05 13:55:04,885 ERROR   SenderThread:190045 [internal_api.py:execute():143] 404 response executing GraphQL.
2022-05-05 13:55:04,885 ERROR   SenderThread:190045 [internal_api.py:execute():144] {"errors":[{"message":"entity classifier not found during upsertBucket","path":["upsertBucket"]}],"data":{"upsertBucket":null}}
2022-05-05 13:55:05,781 INFO    WriterThread:190045 [datastore.py:close():279] close: /home/river/interbotix_ws/src/chessbot/src/wandb/run-20220505_135504-301jv4u6/run-301jv4u6.wandb
2022-05-05 13:55:05,782 INFO    HandlerThread:190045 [handler.py:finish():806] shutting down handler
2022-05-05 13:55:05,782 ERROR   MainThread:190045 [internal.py:wandb_internal():165] Thread SenderThread:
Traceback (most recent call last):
  File "/home/river/.local/lib/python3.8/site-packages/wandb/sdk/lib/retry.py", line 102, in __call__
    result = self._call_fn(*args, **kwargs)
  File "/home/river/.local/lib/python3.8/site-packages/wandb/sdk/internal/internal_api.py", line 140, in execute
    return self.client.execute(*args, **kwargs)
  File "/home/river/.local/lib/python3.8/site-packages/wandb/vendor/gql-0.2.0/wandb_gql/client.py", line 52, in execute
    result = self._get_result(document, *args, **kwargs)
  File "/home/river/.local/lib/python3.8/site-packages/wandb/vendor/gql-0.2.0/wandb_gql/client.py", line 60, in _get_result
    return self.transport.execute(document, *args, **kwargs)
  File "/home/river/.local/lib/python3.8/site-packages/wandb/vendor/gql-0.2.0/wandb_gql/transport/requests.py", line 39, in execute
    request.raise_for_status()
  File "/usr/lib/python3/dist-packages/requests/models.py", line 940, in raise_for_status
    raise HTTPError(http_error_msg, response=self)
requests.exceptions.HTTPError: 404 Client Error: Not Found for url: https://api.wandb.ai/graphql

During handling of the above exception, another exception occurred:

Traceback (most recent call last):
  File "/home/river/.local/lib/python3.8/site-packages/wandb/apis/normalize.py", line 22, in wrapper
    return func(*args, **kwargs)
  File "/home/river/.local/lib/python3.8/site-packages/wandb/sdk/internal/internal_api.py", line 1319, in upsert_run
    response = self.gql(mutation, variable_values=variable_values, **kwargs)
  File "/home/river/.local/lib/python3.8/site-packages/wandb/sdk/lib/retry.py", line 118, in __call__
    if not check_retry_fn(e):
  File "/home/river/.local/lib/python3.8/site-packages/wandb/util.py", line 882, in no_retry_auth
    raise CommError("Permission denied, ask the project owner to grant you access")
wandb.errors.CommError: Permission denied, ask the project owner to grant you access

During handling of the above exception, another exception occurred:

Traceback (most recent call last):
  File "/home/river/.local/lib/python3.8/site-packages/wandb/sdk/internal/internal_util.py", line 51, in run
    self._run()
  File "/home/river/.local/lib/python3.8/site-packages/wandb/sdk/internal/internal_util.py", line 102, in _run
    self._process(record)
  File "/home/river/.local/lib/python3.8/site-packages/wandb/sdk/internal/internal.py", line 310, in _process
    self._sm.send(record)
  File "/home/river/.local/lib/python3.8/site-packages/wandb/sdk/internal/sender.py", line 234, in send
    send_handler(record)
  File "/home/river/.local/lib/python3.8/site-packages/wandb/sdk/internal/sender.py", line 692, in send_run
    self._init_run(run, config_value_dict)
  File "/home/river/.local/lib/python3.8/site-packages/wandb/sdk/internal/sender.py", line 716, in _init_run
    server_run, inserted = self._api.upsert_run(
  File "/home/river/.local/lib/python3.8/site-packages/wandb/apis/normalize.py", line 58, in wrapper
    raise CommError(message, err).with_traceback(sys.exc_info()[2])
  File "/home/river/.local/lib/python3.8/site-packages/wandb/apis/normalize.py", line 22, in wrapper
    return func(*args, **kwargs)
  File "/home/river/.local/lib/python3.8/site-packages/wandb/sdk/internal/internal_api.py", line 1319, in upsert_run
    response = self.gql(mutation, variable_values=variable_values, **kwargs)
  File "/home/river/.local/lib/python3.8/site-packages/wandb/sdk/lib/retry.py", line 118, in __call__
    if not check_retry_fn(e):
  File "/home/river/.local/lib/python3.8/site-packages/wandb/util.py", line 882, in no_retry_auth
    raise CommError("Permission denied, ask the project owner to grant you access")
wandb.errors.CommError: Permission denied, ask the project owner to grant you access
2022-05-05 13:55:07,808 INFO    MainThread:190045 [internal.py:handle_exit():80] Internal process exited
